Workbook

Sheet Assumptions
A1: RLC Model — Assumptions & Inputs (Cu vs SWCNT Bundle Interconnects)
A2: All blue cells are hardcoded inputs/assumptions. Black cells elsewhere in this workbook are live formulas built from these inputs.
A3: Technology nodes: 45nm, 22nm, 14nm, 7nm | Interconnect lengths evaluated: 100 um, 500 um, 1000 um
A5: SECTION A — UNIVERSAL PHYSICAL CONSTANTS
A6: Vacuum permittivity ε0 (F/m) | B6: 8.854e-12 | F6: Standard physical constant
A7: Permeability of free space μ0 (H/m) | B7: 1.2566371e-06 | F7: Standard physical constant = 4*PI()*1e-7
A8: Planck constant h (J·s) | B8: 6.6260701e-34 | F8: CODATA 2018
A9: Electron charge e (C) | B9: 1.6021766e-19 | F9: CODATA 2018
A10: Fermi velocity in metallic SWCNT v_F (m/s) | B10: 800000 | F10: [CNT-L] Naeemi & Meindl 2008; standard value used across CNT interconnect literature
A11: Bulk Cu resistivity rho0 at 21C (Ohm.m) | B11: 1.68e-08 | F11: Standard bulk copper resistivity, 1.68 uOhm.cm
A12: Cu electron mean free path lambda (m) | B12: 3.9e-08 | F12: [Cu-R1] Smith et al., AIP Advances 2019 — lambda = 39 nm at 21C
A13: Operating temperature T (K) | B13: 300 | F13: Assumption: room temperature simulation
A15: SECTION B — GEOMETRY PER TECHNOLOGY NODE (Source: ITRS 2009 / ITRS 2.0 2015 / IRDS 2022 — see original reference doc)
A16: Parameter | B16: 45nm | C16: 22nm | D16: 14nm | E16: 7nm
A17: Wire width W (nm) | B17: 45 | C17: 22 | D17: 14 | E17: 7
A18: Aspect ratio H/W | B18: 1.7 | C18: 1.8 | D18: 1.9 | E18: 2
A19: Wire spacing S (nm) (S = W assumed) | B19: 45 | C19: 22 | D19: 14 | E19: 7
A20: Dielectric constant (ILD) epsilon_r | B20: 3 | C20: 2.7 | D20: 2.5 | E20: 2.3
A21: Barrier (TaN/Ta) thickness (nm) | B21: 3.5 | C21: 2 | D21: 1.5 | E21: 1
A22: CNT diameter d (nm) | B22: 1.6 | C22: 1.2 | D22: 1 | E22: 0.8
A23: Metallic CNT fraction Fm (unsorted synthesis) | B23: 0.33333333 | C23: 0.33333333 | D23: 0.33333333 | E23: 0.33333333
A24: Wire height H (nm) = W * AR | B24: =B17*B18 -> 76.5 | C24: =C17*C18 -> 39.6 | D24: =D17*D18 -> 26.6 | E24: =E17*E18 -> 14
A25: Grain size D (nm) = W (standard assumption D~W) | B25: =B17 -> 45 | C25: =C17 -> 22 | D25: =D17 -> 14 | E25: =E17 -> 7
A27: SECTION C — COPPER-SPECIFIC ASSUMPTIONS
A28: Parameter | B28: 45nm | C28: 22nm | D28: 14nm | E28: 7nm
A29: Specularity parameter p (0=diffuse,1=specular) | B29: 0.5 | C29: 0.5 | D29: -0.2 | E29: -0.2
A30: FS model used | B30: Simplified (d>>lambda) | C30: Simplified (d>>lambda) | D30: Full FS integral | E30: Full FS integral
A31: GB reflection coefficient R (MS model) | B31: 0.165 | C31: 0.165 | D31: 0.165 | E31: 0.165
A32: rho_FS multiplier (rho_FS/rho0) — 45/22nm via closed-form simplified formula 1+(3*lambda/8d)(1-p); 14/7nm via full FS integral, evaluated numerically in Python (Simpson's rule, 20000 pts) since Excel cannot evaluate the improper integral natively. See Notes sheet. | B32: =1+(3*B12*1000000000/(8*MIN(B17,B24)))*(1-B29) -> 1.1625 | C32: =1+(3*B12*1000000000/(8*MIN(C17,C24)))*(1-C29) -> 1.3323864 | D32: 2.601184 | E32: 3.984279
A34: SECTION D — SWCNT BUNDLE-SPECIFIC ASSUMPTIONS
A35: Inter-tube van der Waals spacing delta (nm) | B35: 0.34 | F35: [CNT-R1] MDPI Crystals 2022
A36: Acoustic phonon MFP lambda_AC at T=300K (nm) = 400/(T/300) | B36: 400 | F36: [CNT-R2] Park et al. 2004; formula uses T from Section A
A37: Optical phonon MFP lambda_OP (nm), ~T-independent | B37: 56 | F37: [CNT-R2] Park et al. 2004
A38: Metal-CNT contact resistance R_contact (Ohm) — ASSUMPTION: mid/typical simulation value (range in lit: 3.2k-100k) | B38: 10000 | F38: [CNT-R1] MDPI Crystals 2022 notes 3.2k as best-case Pd-contact lower bound; 10k used here as typical simulation value — STATE/CHANGE THIS if your project specifies a different contact quality
A39: Bundle center height y above ground plane — ASSUMPTION: y = wire height H (same plane geometry as Cu model) | B39: 1 | F39: Assumption (not explicit in source formula); y taken equal to per-node H
A40: Bundle effective diameter d_bundle — ASSUMPTION: sqrt(W*H), equivalent circular cross-section of the W x H envelope | F40: Assumption (not explicit in source formula)
A42: Notes / methodology caveats:
A43: 1. Cu resistivity: 45nm/22nm use the simplified FS approximation (valid d>>lambda); 14nm/7nm use the full FS integral evaluated numerically in Python because Excel/LibreOffice cannot evaluate this improper integral natively. Specularity p=0.5 assumed for 45/22nm (not explicitly given in source; typical partially-specular literature value); p=-0.2 used for 14/7nm per source's explicit recommendation.
A44: 2. MS grain-boundary reflection coefficient R taken as 0.165 (midpoint of source's cited 0.16-0.17 range).
A45: 3. Cu inductance (L_self) is a function of total wire length l (not purely per-unit-length) via the Neumann formula's ln(2l/(W+H)) term — computed separately for each of the 3 lengths.
...

Sheet Cu
A1: Copper Interconnect — R, L, C Calculation
A2: All formulas reference the Assumptions sheet. Change any blue input there and this sheet recalculates.
A4: STEP 1 — Per-Unit-Length Resistivity & Resistance
A5: Quantity | B5: 45nm | C5: 22nm | D5: 14nm | E5: 7nm
A6: rho_FS multiplier (rho_FS/rho0) [Assumptions!rho_fs_mult] | B6: =Assumptions!B32 -> 1.1625 | C6: =Assumptions!C32 -> 1.3323864 | D6: =Assumptions!D32 -> 2.601184 | E6: =Assumptions!E32 -> 3.984279
A7: alpha = (lambda/D) * R/(1-R) [MS model] | B7: =(Assumptions!$B$12*1000000000/Assumptions!B25)*Assumptions!B31/(1-Assumptions!B31) -> 0.17125749 | C7: =(Assumptions!$B$12*1000000000/Assumptions!C25)*Assumptions!C31/(1-Assumptions!C31) -> 0.3502994 | D7: =(Assumptions!$B$12*1000000000/Assumptions!D25)*Assumptions!D31/(1-Assumptions!D31) -> 0.55047049 | E7: =(Assumptions!$B$12*1000000000/Assumptions!E25)*Assumptions!E31/(1-Assumptions!E31) -> 1.100941
A8: rho_MS multiplier (rho_MS/rho0) | B8: =1/(1-1.5*B7+3*B7^2-3*B7^3*LN(1+1/B7)) -> 1.2466815 | C8: =1/(1-1.5*C7+3*C7^2-3*C7^3*LN(1+1/C7)) -> 1.4954808 | D8: =1/(1-1.5*D7+3*D7^2-3*D7^3*LN(1+1/D7)) -> 1.7694233 | E8: =1/(1-1.5*E7+3*E7^2-3*E7^3*LN(1+1/E7)) -> 2.5137172
A9: rho_eff = rho_FS_mult * rho0 * rho_MS_mult (Ohm.m) | B9: =B6*Assumptions!$B$11*B8 -> 2.434769e-08 | C9: =C6*Assumptions!$B$11*C8 -> 3.3474978e-08 | D9: =D6*Assumptions!$B$11*D8 -> 7.7323605e-08 | E9: =E6*Assumptions!$B$11*E8 -> 1.6825789e-07
A10: rho_eff (uOhm.cm) — sanity check vs bulk 1.68 | B10: =B9*100000000 -> 2.434769 | C10: =C9*100000000 -> 3.3474978 | D10: =D9*100000000 -> 7.7323605 | E10: =E9*100000000 -> 16.825789
A11: W_eff = W - 2*t_barrier (nm) | B11: =Assumptions!B17-2*Assumptions!B21 -> 38 | C11: =Assumptions!C17-2*Assumptions!C21 -> 18 | D11: =Assumptions!D17-2*Assumptions!D21 -> 11 | E11: =Assumptions!E17-2*Assumptions!E21 -> 5
A12: H_eff = H - t_barrier (nm) | B12: =Assumptions!B24-Assumptions!B21 -> 73 | C12: =Assumptions!C24-Assumptions!C21 -> 37.6 | D12: =Assumptions!D24-Assumptions!D21 -> 25.1 | E12: =Assumptions!E24-Assumptions!E21 -> 13
A13: R per unit length = rho_eff / (W_eff*H_eff) (Ohm/m) | B13: =B9/((B11*0.000000001)*(B12*0.000000001)) -> 8777105.3 | C13: =C9/((C11*0.000000001)*(C12*0.000000001)) -> 49460665 | D13: =D9/((D11*0.000000001)*(D12*0.000000001)) -> 2.8005652e+08 | E13: =E9/((E11*0.000000001)*(E12*0.000000001)) -> 2.588583e+09
A15: STEP 2 — Per-Unit-Length Capacitance (Sakurai-Tamaru, ITRS-fitted coefficients)
A16: C per unit length = eps0*epsr*[W/H + 2.04(S/(S+0.54H))^1.77 + 1.14(W/H)^0.06(S/(S+1.51H))^4.53] (F/m) | B16: =Assumptions!$B$6*Assumptions!B20*( Assumptions!B17/Assumptions!B24 + 2.04*(Assumptions!B19/(Assumptions!B19+0.54*Assumptions!B24))^1.77 + 1.14*(Assumptions!B17/Assumptions!B24)^0.06*(Assumptions!B19/(Assumptions!B19+1.51*Assumptions!B24))^4.53 ) -> 3.2827006e-11 | C16: =Assumptions!$B$6*Assumptions!C20*( Assumptions!C17/Assumptions!C24 + 2.04*(Assumptions!C19/(Assumptions!C19+0.54*Assumptions!C24))^1.77 + 1.14*(Assumptions!C17/Assumptions!C24)^0.06*(Assumptions!C19/(Assumptions!C19+1.51*Assumptions!C24))^4.53 ) -> 2.8010123e-11 | D16: =Assumptions!$B$6*Assumptions!D20*( Assumptions!D17/Assumptions!D24 + 2.04*(Assumptions!D19/(Assumptions!D19+0.54*Assumptions!D24))^1.77 + 1.14*(Assumptions!D17/Assumptions!D24)^0.06*(Assumptions!D19/(Assumptions!D19+1.51*Assumptions!D24))^4.53 ) -> 2.4643601e-11 | E16: =Assumptions!$B$6*Assumptions!E20*( Assumptions!E17/Assumptions!E24 + 2.04*(Assumptions!E19/(Assumptions!E19+0.54*Assumptions!E24))^1.77 + 1.14*(Assumptions!E17/Assumptions!E24)^0.06*(Assumptions!E19/(Assumptions!E19+1.51*Assumptions!E24))^4.53 ) -> 2.1586739e-11
A18: STEP 3 — Totals for Interconnect Lengths 100 / 500 / 1000 um
A19: Inductance uses the Neumann formula for a rectangular wire L_self=(mu0/2pi)[ln(2l/(W+H))+0.5+0.2235(W+H)/l]; this depends on total length l, so R, L, C totals are computed separately per length below.
A21: Length = 100 um
A22: Result | B22: 45nm | C22: 22nm | D22: 14nm | E22: 7nm
A23: Total Resistance R (Ohm) | B23: =B13*100*0.000001 -> 877.71053 | C23: =C13*100*0.000001 -> 4946.0665 | D23: =D13*100*0.000001 -> 28005.652 | E23: =E13*100*0.000001 -> 258858.3
A24: Total Self-Inductance L (nH) [Neumann formula] | B24: =(Assumptions!$B$7/(2*PI()))*(100*0.000001)*(LN(2*(100*0.000001)/((Assumptions!B17+Assumptions!B24)*0.000000001))+0.5+0.2235*((Assumptions!B17+Assumptions!B24)*0.000000001)/(100*0.000001))*1000000000 -> 0.1581286 | C24: =(Assumptions!$B$7/(2*PI()))*(100*0.000001)*(LN(2*(100*0.000001)/((Assumptions!C17+Assumptions!C24)*0.000000001))+0.5+0.2235*((Assumptions!C17+Assumptions!C24)*0.000000001)/(100*0.000001))*1000000000 -> 0.17171097 | D24: =(Assumptions!$B$7/(2*PI()))*(100*0.000001)*(LN(2*(100*0.000001)/((Assumptions!D17+Assumptions!D24)*0.000000001))+0.5+0.2235*((Assumptions!D17+Assumptions!D24)*0.000000001)/(100*0.000001))*1000000000 -> 0.18004791 | E24: =(Assumptions!$B$7/(2*PI()))*(100*0.000001)*(LN(2*(100*0.000001)/((Assumptions!E17+Assumptions!E24)*0.000000001))+0.5+0.2235*((Assumptions!E17+Assumptions!E24)*0.000000001)/(100*0.000001))*1000000000 -> 0.19323194
A25: Total Capacitance C (fF) | B25: =B16*100*0.000001*1000000000000000 -> 3.2827006 | C25: =C16*100*0.000001*1000000000000000 -> 2.8010123 | D25: =D16*100*0.000001*1000000000000000 -> 2.4643601 | E25: =E16*100*0.000001*1000000000000000 -> 2.1586739
A27: Length = 500 um
A28: Result | B28: 45nm | C28: 22nm | D28: 14nm | E28: 7nm
A29: Total Resistance R (Ohm) | B29: =B13*500*0.000001 -> 4388.5527 | C29: =C13*500*0.000001 -> 24730.332 | D29: =D13*500*0.000001 -> 140028.26 | E29: =E13*500*0.000001 -> 1294291.5
A30: Total Self-Inductance L (nH) [Neumann formula] | B30: =(Assumptions!$B$7/(2*PI()))*(500*0.000001)*(LN(2*(500*0.000001)/((Assumptions!B17+Assumptions!B24)*0.000000001))+0.5+0.2235*((Assumptions!B17+Assumptions!B24)*0.000000001)/(500*0.000001))*1000000000 -> 0.95156506 | C30: =(Assumptions!$B$7/(2*PI()))*(500*0.000001)*(LN(2*(500*0.000001)/((Assumptions!C17+Assumptions!C24)*0.000000001))+0.5+0.2235*((Assumptions!C17+Assumptions!C24)*0.000000001)/(500*0.000001))*1000000000 -> 1.0194876 | D30: =(Assumptions!$B$7/(2*PI()))*(500*0.000001)*(LN(2*(500*0.000001)/((Assumptions!D17+Assumptions!D24)*0.000000001))+0.5+0.2235*((Assumptions!D17+Assumptions!D24)*0.000000001)/(500*0.000001))*1000000000 -> 1.0611761 | E30: =(Assumptions!$B$7/(2*PI()))*(500*0.000001)*(LN(2*(500*0.000001)/((Assumptions!E17+Assumptions!E24)*0.000000001))+0.5+0.2235*((Assumptions!E17+Assumptions!E24)*0.000000001)/(500*0.000001))*1000000000 -> 1.1270998
A31: Total Capacitance C (fF) | B31: =B16*500*0.000001*1000000000000000 -> 16.413503 | C31: =C16*500*0.000001*1000000000000000 -> 14.005061 | D31: =D16*500*0.000001*1000000000000000 -> 12.321801 | E31: =E16*500*0.000001*1000000000000000 -> 10.79337
A33: Length = 1000 um
A34: Result | B34: 45nm | C34: 22nm | D34: 14nm | E34: 7nm
A35: Total Resistance R (Ohm) | B35: =B13*1000*0.000001 -> 8777.1053 | C35: =C13*1000*0.000001 -> 49460.665 | D35: =D13*1000*0.000001 -> 280056.52 | E35: =E13*1000*0.000001 -> 2588583
A36: Total Self-Inductance L (nH) [Neumann formula] | B36: =(Assumptions!$B$7/(2*PI()))*(1000*0.000001)*(LN(2*(1000*0.000001)/((Assumptions!B17+Assumptions!B24)*0.000000001))+0.5+0.2235*((Assumptions!B17+Assumptions!B24)*0.000000001)/(1000*0.000001))*1000000000 -> 2.0417541 | C36: =(Assumptions!$B$7/(2*PI()))*(1000*0.000001)*(LN(2*(1000*0.000001)/((Assumptions!C17+Assumptions!C24)*0.000000001))+0.5+0.2235*((Assumptions!C17+Assumptions!C24)*0.000000001)/(1000*0.000001))*1000000000 -> 2.1776019 | D36: =(Assumptions!$B$7/(2*PI()))*(1000*0.000001)*(LN(2*(1000*0.000001)/((Assumptions!D17+Assumptions!D24)*0.000000001))+0.5+0.2235*((Assumptions!D17+Assumptions!D24)*0.000000001)/(1000*0.000001))*1000000000 -> 2.2609797 | E36: =(Assumptions!$B$7/(2*PI()))*(1000*0.000001)*(LN(2*(1000*0.000001)/((Assumptions!E17+Assumptions!E24)*0.000000001))+0.5+0.2235*((Assumptions!E17+Assumptions!E24)*0.000000001)/(1000*0.000001))*1000000000 -> 2.392828
A37: Total Capacitance C (fF) | B37: =B16*1000*0.000001*1000000000000000 -> 32.827006 | C37: =C16*1000*0.000001*1000000000000000 -> 28.010123 | D37: =D16*1000*0.000001*1000000000000000 -> 24.643601 | E37: =E16*1000*0.000001*1000000000000000 -> 21.586739

Sheet CNT
A1: SWCNT Bundle Interconnect — R, L, C Calculation
A2: All formulas reference the Assumptions sheet. Change any blue input there and this sheet recalculates.
A4: STEP 1 — Bundle Geometry
A5: Quantity | B5: 45nm | C5: 22nm | D5: 14nm | E5: 7nm
A6: N_total = INT(W/(d+delta)) * INT(H/(d+delta)) | B6: =INT(Assumptions!B17/(Assumptions!B22+Assumptions!$B$35))*INT(Assumptions!B24/(Assumptions!B22+Assumptions!$B$35)) -> 897 | C6: =INT(Assumptions!C17/(Assumptions!C22+Assumptions!$B$35))*INT(Assumptions!C24/(Assumptions!C22+Assumptions!$B$35)) -> 350 | D6: =INT(Assumptions!D17/(Assumptions!D22+Assumptions!$B$35))*INT(Assumptions!D24/(Assumptions!D22+Assumptions!$B$35)) -> 190 | E6: =INT(Assumptions!E17/(Assumptions!E22+Assumptions!$B$35))*INT(Assumptions!E24/(Assumptions!E22+Assumptions!$B$35)) -> 72
A7: N_m = ROUND(N_total * Fm, 0) [metallic CNTs] | B7: =ROUND(B6*Assumptions!B23,0) -> 299 | C7: =ROUND(C6*Assumptions!C23,0) -> 117 | D7: =ROUND(D6*Assumptions!D23,0) -> 63 | E7: =ROUND(E6*Assumptions!E23,0) -> 24
A9: STEP 2 — Effective Mean Free Path & Per-CNT Quantum Resistance (node-independent)
A10: lambda_AC = 400/(T/300) (nm) | B10: =Assumptions!$B$36/(Assumptions!$B$13/300) -> 400
A11: lambda_OP (nm) | B11: =Assumptions!$B$37 -> 56
A12: lambda_eff = 1/(1/lambda_AC + 1/lambda_OP) (nm) | B12: =1/(1/B10+1/B11) -> 49.122807
A13: R_Q = h/(4*e^2) (Ohm) [quantum/contact resistance, 4 channels] | B13: =Assumptions!$B$8/(4*Assumptions!$B$9^2) -> 6453.2019
A15: STEP 3 — Per-Unit-Length Inductance & Capacitance
A16: L_K_tube = h/(4*e^2*vF) (H/m) [kinetic inductance, per CNT, all 4 channels] | B16: =Assumptions!$B$8/(4*Assumptions!$B$9^2*Assumptions!$B$10) -> 0.0080665023
A17: L_K_bundle = L_K_tube / N_m (H/m) | B17: =$B$16/B7 -> 2.6978269e-05 | C17: =$B$16/C7 -> 6.8944464e-05 | D17: =$B$16/D7 -> 0.00012803972 | E17: =$B$16/E7 -> 0.00033610426
A18: L_M = (mu0/2pi)*LN(2H/W+1) (H/m) [magnetic inductance] | B18: =(Assumptions!$B$7/(2*PI()))*LN(2*Assumptions!B24/Assumptions!B17+1) -> 2.9632091e-07 | C18: =(Assumptions!$B$7/(2*PI()))*LN(2*Assumptions!C24/Assumptions!C17+1) -> 3.0521126e-07 | D18: =(Assumptions!$B$7/(2*PI()))*LN(2*Assumptions!D24/Assumptions!D17+1) -> 3.1372318e-07 | E18: =(Assumptions!$B$7/(2*PI()))*LN(2*Assumptions!E24/Assumptions!E17+1) -> 3.2188758e-07
A19: L per unit length = L_K_bundle + L_M (H/m) | B19: =B17+B18 -> 2.727459e-05 | C19: =C17+C18 -> 6.9249676e-05 | D19: =D17+D18 -> 0.00012835344 | E19: =E17+E18 -> 0.00033642615
A20: C_Q = 4*e^2/(h*vF) (F/m) [quantum cap., per CNT] | B20: =4*Assumptions!$B$9^2/(Assumptions!$B$8*Assumptions!$B$10) -> 1.9370229e-10
A21: C_Q_bundle = C_Q * N_m (F/m) | B21: =$B$20*B7 -> 5.7916986e-08 | C21: =$B$20*C7 -> 2.2663168e-08 | D21: =$B$20*D7 -> 1.2203244e-08 | E21: =$B$20*E7 -> 4.648855e-09
A22: Bundle effective diameter d_bundle = SQRT(W*H) (nm) [assumption] | B22: =SQRT(Assumptions!B17*Assumptions!B24) -> 58.672822 | C22: =SQRT(Assumptions!C17*Assumptions!C24) -> 29.516097 | D22: =SQRT(Assumptions!D17*Assumptions!D24) -> 19.297668 | E22: =SQRT(Assumptions!E17*Assumptions!E24) -> 9.8994949
A23: C_E = 2*pi*eps0*epsr / LN(2y/d_bundle) (F/m) [y = H, per assumption] | B23: =2*PI()*Assumptions!$B$6*Assumptions!B20/LN(2*(Assumptions!B24*Assumptions!$B$39)/B22) -> 1.7412698e-10 | C23: =2*PI()*Assumptions!$B$6*Assumptions!C20/LN(2*(Assumptions!C24*Assumptions!$B$39)/C22) -> 1.521767e-10 | D23: =2*PI()*Assumptions!$B$6*Assumptions!D20/LN(2*(Assumptions!D24*Assumptions!$B$39)/D22) -> 1.3714807e-10 | E23: =2*PI()*Assumptions!$B$6*Assumptions!E20/LN(2*(Assumptions!E24*Assumptions!$B$39)/E22) -> 1.2306385e-10
A24: C per unit length (series C_Q_bundle & C_E) = (CQb*CE)/(CQb+CE) (F/m) | B24: =(B21*B23)/(B21+B23) -> 1.7360503e-10 | C24: =(C21*C23)/(C21+C23) -> 1.511617e-10 | D24: =(D21*D23)/(D21+D23) -> 1.3562384e-10 | E24: =(E21*E23)/(E21+E23) -> 1.1989014e-10
A26: STEP 4 — Totals for Interconnect Lengths 100 / 500 / 1000 um
A27: R_scatter = R_Q*(L/lambda_eff) grows with length, so bundle resistance is computed per length. L and C per-unit-length quantities above are simply multiplied by length.
A29: Length = 100 um
A30: Result | B30: 45nm | C30: 22nm | D30: 14nm | E30: 7nm
A31: Total Bundle Resistance R (Ohm) = (R_Q + R_Q*(L/lambda_eff) + R_contact) / N_m | B31: =($B$13+$B$13*((100*1000)/$B$12)+Assumptions!$B$38)/B7 -> 43991.065 | C31: =($B$13+$B$13*((100*1000)/$B$12)+Assumptions!$B$38)/C7 -> 112421.61 | D31: =($B$13+$B$13*((100*1000)/$B$12)+Assumptions!$B$38)/D7 -> 208782.99 | E31: =($B$13+$B$13*((100*1000)/$B$12)+Assumptions!$B$38)/E7 -> 548055.35
A32: Total Inductance L (nH) = L_per_len * length | B32: =B19*100*0.000001*1000000000 -> 2.727459 | C32: =C19*100*0.000001*1000000000 -> 6.9249676 | D32: =D19*100*0.000001*1000000000 -> 12.835344 | E32: =E19*100*0.000001*1000000000 -> 33.642615
A33: Total Capacitance C (fF) = C_per_len * length | B33: =B24*100*0.000001*1000000000000000 -> 17.360503 | C33: =C24*100*0.000001*1000000000000000 -> 15.11617 | D33: =D24*100*0.000001*1000000000000000 -> 13.562384 | E33: =E24*100*0.000001*1000000000000000 -> 11.989014
A35: Length = 500 um
A36: Result | B36: 45nm | C36: 22nm | D36: 14nm | E36: 7nm
A37: Total Bundle Resistance R (Ohm) = (R_Q + R_Q*(L/lambda_eff) + R_contact) / N_m | B37: =($B$13+$B$13*((500*1000)/$B$12)+Assumptions!$B$38)/B7 -> 219735.22 | C37: =($B$13+$B$13*((500*1000)/$B$12)+Assumptions!$B$38)/C7 -> 561545.55 | D37: =($B$13+$B$13*((500*1000)/$B$12)+Assumptions!$B$38)/D7 -> 1042870.3 | E37: =($B$13+$B$13*((500*1000)/$B$12)+Assumptions!$B$38)/E7 -> 2737534.6
A38: Total Inductance L (nH) = L_per_len * length | B38: =B19*500*0.000001*1000000000 -> 13.637295 | C38: =C19*500*0.000001*1000000000 -> 34.624838 | D38: =D19*500*0.000001*1000000000 -> 64.176721 | E38: =E19*500*0.000001*1000000000 -> 168.21308
A39: Total Capacitance C (fF) = C_per_len * length | B39: =B24*500*0.000001*1000000000000000 -> 86.802517 | C39: =C24*500*0.000001*1000000000000000 -> 75.580848 | D39: =D24*500*0.000001*1000000000000000 -> 67.811919 | E39: =E24*500*0.000001*1000000000000000 -> 59.945068
A41: Length = 1000 um
A42: Result | B42: 45nm | C42: 22nm | D42: 14nm | E42: 7nm
A43: Total Bundle Resistance R (Ohm) = (R_Q + R_Q*(L/lambda_eff) + R_contact) / N_m | B43: =($B$13+$B$13*((1000*1000)/$B$12)+Assumptions!$B$38)/B7 -> 439415.4 | C43: =($B$13+$B$13*((1000*1000)/$B$12)+Assumptions!$B$38)/C7 -> 1122950.5 | D43: =($B$13+$B$13*((1000*1000)/$B$12)+Assumptions!$B$38)/D7 -> 2085479.5 | E43: =($B$13+$B$13*((1000*1000)/$B$12)+Assumptions!$B$38)/E7 -> 5474383.6
A44: Total Inductance L (nH) = L_per_len * length | B44: =B19*1000*0.000001*1000000000 -> 27.27459 | C44: =C19*1000*0.000001*1000000000 -> 69.249676 | D44: =D19*1000*0.000001*1000000000 -> 128.35344 | E44: =E19*1000*0.000001*1000000000 -> 336.42615
A45: Total Capacitance C (fF) = C_per_len * length | B45: =B24*1000*0.000001*1000000000000000 -> 173.60503 | C45: =C24*1000*0.000001*1000000000000000 -> 151.1617 | D45: =D24*1000*0.000001*1000000000000000 -> 135.62384 | E45: =E24*1000*0.000001*1000000000000000 -> 119.89014

Sheet Summary
A1: Summary — Cu vs SWCNT Bundle: R, L, C for All Nodes and Lengths
A2: Pulled live from the Cu and CNT calculation sheets. Units: R in Ohm, L in nH, C in fF.
A4: INTERCONNECT LENGTH = 100 um
A5: Node | B5: Material | C5: R (Ohm) | D5: L (nH) | E5: C (fF)
A6: 45nm | B6: Cu | C6: =Cu!B23 -> 877.71053 | D6: =Cu!B24 -> 0.1581286 | E6: =Cu!B25 -> 3.2827006
A7: 45nm | B7: CNT | C7: =CNT!B31 -> 43991.065 | D7: =CNT!B32 -> 2.727459 | E7: =CNT!B33 -> 17.360503
A8: 22nm | B8: Cu | C8: =Cu!C23 -> 4946.0665 | D8: =Cu!C24 -> 0.17171097 | E8: =Cu!C25 -> 2.8010123
A9: 22nm | B9: CNT | C9: =CNT!C31 -> 112421.61 | D9: =CNT!C32 -> 6.9249676 | E9: =CNT!C33 -> 15.11617
A10: 14nm | B10: Cu | C10: =Cu!D23 -> 28005.652 | D10: =Cu!D24 -> 0.18004791 | E10: =Cu!D25 -> 2.4643601
A11: 14nm | B11: CNT | C11: =CNT!D31 -> 208782.99 | D11: =CNT!D32 -> 12.835344 | E11: =CNT!D33 -> 13.562384
A12: 7nm | B12: Cu | C12: =Cu!E23 -> 258858.3 | D12: =Cu!E24 -> 0.19323194 | E12: =Cu!E25 -> 2.1586739
A13: 7nm | B13: CNT | C13: =CNT!E31 -> 548055.35 | D13: =CNT!E32 -> 33.642615 | E13: =CNT!E33 -> 11.989014
A15: INTERCONNECT LENGTH = 500 um
A16: Node | B16: Material | C16: R (Ohm) | D16: L (nH) | E16: C (fF)
A17: 45nm | B17: Cu | C17: =Cu!B29 -> 4388.5527 | D17: =Cu!B30 -> 0.95156506 | E17: =Cu!B31 -> 16.413503
A18: 45nm | B18: CNT | C18: =CNT!B37 -> 219735.22 | D18: =CNT!B38 -> 13.637295 | E18: =CNT!B39 -> 86.802517
A19: 22nm | B19: Cu | C19: =Cu!C29 -> 24730.332 | D19: =Cu!C30 -> 1.0194876 | E19: =Cu!C31 -> 14.005061
A20: 22nm | B20: CNT | C20: =CNT!C37 -> 561545.55 | D20: =CNT!C38 -> 34.624838 | E20: =CNT!C39 -> 75.580848
A21: 14nm | B21: Cu | C21: =Cu!D29 -> 140028.26 | D21: =Cu!D30 -> 1.0611761 | E21: =Cu!D31 -> 12.321801
A22: 14nm | B22: CNT | C22: =CNT!D37 -> 1042870.3 | D22: =CNT!D38 -> 64.176721 | E22: =CNT!D39 -> 67.811919
A23: 7nm | B23: Cu | C23: =Cu!E29 -> 1294291.5 | D23: =Cu!E30 -> 1.1270998 | E23: =Cu!E31 -> 10.79337
A24: 7nm | B24: CNT | C24: =CNT!E37 -> 2737534.6 | D24: =CNT!E38 -> 168.21308 | E24: =CNT!E39 -> 59.945068
A26: INTERCONNECT LENGTH = 1000 um
A27: Node | B27: Material | C27: R (Ohm) | D27: L (nH) | E27: C (fF)
A28: 45nm | B28: Cu | C28: =Cu!B35 -> 8777.1053 | D28: =Cu!B36 -> 2.0417541 | E28: =Cu!B37 -> 32.827006
A29: 45nm | B29: CNT | C29: =CNT!B43 -> 439415.4 | D29: =CNT!B44 -> 27.27459 | E29: =CNT!B45 -> 173.60503
A30: 22nm | B30: Cu | C30: =Cu!C35 -> 49460.665 | D30: =Cu!C36 -> 2.1776019 | E30: =Cu!C37 -> 28.010123
A31: 22nm | B31: CNT | C31: =CNT!C43 -> 1122950.5 | D31: =CNT!C44 -> 69.249676 | E31: =CNT!C45 -> 151.1617
A32: 14nm | B32: Cu | C32: =Cu!D35 -> 280056.52 | D32: =Cu!D36 -> 2.2609797 | E32: =Cu!D37 -> 24.643601
A33: 14nm | B33: CNT | C33: =CNT!D43 -> 2085479.5 | D33: =CNT!D44 -> 128.35344 | E33: =CNT!D45 -> 135.62384
A34: 7nm | B34: Cu | C34: =Cu!E35 -> 2588583 | D34: =Cu!E36 -> 2.392828 | E34: =Cu!E37 -> 21.586739
A35: 7nm | B35: CNT | C35: =CNT!E43 -> 5474383.6 | D35: =CNT!E44 -> 336.42615 | E35: =CNT!E45 -> 119.89014
A38: How to use this sheet:
A39: - Assumptions sheet: every input value (geometry, physical constants, and stated modeling assumptions) with sources — edit blue cells only.
A40: - Cu sheet: step-by-step resistivity/capacitance/inductance derivation for copper, ending in R/L/C totals per node and length.
A41: - CNT sheet: step-by-step SWCNT bundle derivation, ending in R/L/C totals per node and length.
A42: - This Summary sheet: the final numbers you'll actually plug into ngspice/MATLAB, side by side for Cu vs CNT.
A43: - To change an assumption (e.g. R_contact, specularity p, or Fm for sorted CNTs), edit it once in Assumptions — every sheet recalculates automatically.
